<?xml version="1.0" encoding="utf-8"?>


<!-- This URDF was automatically created by SolidWorks to URDF Exporter! Originally created by Stephen Brawner (brawner@gmail.com) 
     Commit Version: 1.6.0-4-g7f85cfe  Build Version: 1.6.7995.38578
     For more information, please see http://wiki.ros.org/sw_urdf_exporter -->
<robot
  name="Robot_URDF" 
  xmlns:xacro="http://www.ros.org/wiki/xacro">

    <!-- Import Rviz colors -->
    <xacro:include filename="$(find Robot_URDF)/urdf/materials.xacro" />

<!-- Import all Gazebo-customization elements, including Gazebo colors -->
  <xacro:include filename="$(find Robot_URDF)/urdf/mybot.gazebo" />

  <link
    name="base_link">
    <inertial>
      <origin
        xyz="0.0017553 -2.9398E-07 0.0177"
        rpy="0 0 0" />
      <mass
        value="0.33739" />
      <inertia
        ixx="0.0028468"
        ixy="6.2586E-10"
        ixz="1.4453E-06"
        iyy="0.0028585"
        iyz="2.2404E-09"
        izz="0.0053109" />
    </inertial>
    <visual>
      <origin
        xyz="0 0 0"
        rpy="0 0 0" />
      <geometry>
        <mesh
          filename="package://Robot_URDF/meshes/base_link.STL" />
      </geometry>
      <material name="white"/>
    </visual>
    <collision>
      <origin
        xyz="0 0 0"
        rpy="0 0 0" />
      <geometry>
        <mesh
          filename="package://Robot_URDF/meshes/base_link.STL" />
      </geometry>
    </collision>
  </link>
  <link

    name="RightWheel_Link">
    <inertial>
      <origin
        xyz="-0.047215 -0.086543 0.014931"
        rpy="0 0 0" />
      <mass
        value="0.30664" />
      <inertia
        ixx="0.00012023"
        ixy="6.996E-14"
        ixz="-1.216E-13"
        iyy="0.0002214"
        iyz="-6.3898E-14"
        izz="0.00012023" />
    </inertial>
    <visual>
      <origin
        xyz="0 0 0"
        rpy="0 0 0" />
      <geometry>
        <mesh
          filename="package://Robot_URDF/meshes/RightWheel_Link.STL" />
      </geometry>
      <material name="black"/>
    </visual>
    <collision>
      <origin
        xyz="0 0 0"
        rpy="0 0 0" />
      <geometry>
        <mesh
          filename="package://Robot_URDF/meshes/RightWheel_Link.STL" />
      </geometry>
    </collision>
  </link>
  <joint
  
    name="RightWheel_Joint"
    type="revolute">
    <origin
      xyz="0 0 0"
      rpy="0 0 0" />
    <parent
      link="base_link" />
    <child
      link="RightWheel_Link" />
    <axis
      xyz="0 -1 0" />
    <limit
      lower="-3.1416"
      upper="3.1416"
      effort="20"
      velocity="5" />
  </joint>
  <link

    name="LeftWheel_Link">
    <inertial>
      <origin
        xyz="-0.047215 0.086449 0.014931"
        rpy="0 0 0" />
      <mass
        value="0.30664" />
      <inertia
        ixx="0.00012023"
        ixy="-6.9962E-14"
        ixz="1.216E-13"
        iyy="0.0002214"
        iyz="-6.3898E-14"
        izz="0.00012023" />
    </inertial>
    <visual>
      <origin
        xyz="0 0 0"
        rpy="0 0 0" />
      <geometry>
        <mesh
          filename="package://Robot_URDF/meshes/LeftWheel_Link.STL" />
      </geometry>
      <material name="black"/>
    </visual>
    <collision>
      <origin
        xyz="0 0 0"
        rpy="0 0 0" />
      <geometry>
        <mesh
          filename="package://Robot_URDF/meshes/LeftWheel_Link.STL" />
      </geometry>
    </collision>
  </link>
  <joint

    name="LeftWheel_Joint"
    type="revolute">
    <origin
      xyz="0 0 0"
      rpy="0 0 0" />
    <parent
      link="base_link" />
    <child
      link="LeftWheel_Link" />
    <axis
      xyz="0 1 0" />
    <limit
      lower="-3.1416"
      upper="3.1416"
      effort="20"
      velocity="5" />
  </joint>
  <link

    name="CasterWheel_Link">
    <inertial>
      <origin
        xyz="0.074896 0.00010413 -0.0057749"
        rpy="0 0 0" />
      <mass
        value="0.0066846" />
      <inertia
        ixx="4.665E-07"
        ixy="1.9714E-22"
        ixz="-3.4365E-25"
        iyy="4.665E-07"
        iyz="-7.5603E-24"
        izz="8.8561E-07" />
    </inertial>
    <visual>
      <origin
        xyz="0 0 0"
        rpy="0 0 0" />
      <geometry>
        <mesh
          filename="package://Robot_URDF/meshes/CasterWheel_Link.STL" />
      </geometry>
      <material name="blue"/>
    </visual>
    <collision>
      <origin
        xyz="0 0 0"
        rpy="0 0 0" />
      <geometry>
        <mesh
          filename="package://Robot_URDF/meshes/CasterWheel_Link.STL" />
      </geometry>
    </collision>
  </link>
  <joint

  
    name="CasterWheel_Joint"
    type="fixed">
    <origin
      xyz="0 0 0"
      rpy="0 0 0" />
    <parent
      link="base_link" />
    <child

      link="CasterWheel_Link" />
    <axis
      xyz="0 0 0" />
  </joint>
  <link

    name="RightUltra_Link">
    <inertial>
      <origin
        xyz="-4.2017E-06 -0.14835 0.040053"
        rpy="0 0 0" />
      <mass
        value="0.0062273" />
      <inertia
        ixx="2.3852E-07"
        ixy="1.3189E-10"
        ixz="1.9966E-10"
        iyy="1.2204E-06"
        iyz="2.0237E-09"
        izz="1.1941E-06" />
    </inertial>
    <visual>
      <origin
        xyz="0 0 0"
        rpy="0 0 0" />
      <geometry>
        <mesh
          filename="package://Robot_URDF/meshes/RightUltra_Link.STL" />
      </geometry>
      <material name="green"/>
    </visual>
    <collision>
      <origin
        xyz="0 0 0"
        rpy="0 0 0" />
      <geometry>
        <mesh
          filename="package://Robot_URDF/meshes/RightUltra_Link.STL" />
      </geometry>
    </collision>
  </link>
  <joint


    name="RightUltra_Joint"
    type="fixed">
    <origin
      xyz="0 0 0"
      rpy="0 0 0" />
    <parent


      link="base_link" />
    <child
      link="RightUltra_Link" />
    <axis
      xyz="0 0 0" />
  </joint>
  <link
    name="FrontUltra_Link">
    <inertial>
      <origin
        xyz="0.14829 -4.2017E-06 0.040053"
        rpy="0 0 0" />
      <mass
        value="0.0062273" />
      <inertia
        ixx="1.2204E-06"
        ixy="-1.3189E-10"
        ixz="-2.0237E-09"
        iyy="2.3852E-07"
        iyz="1.9966E-10"
        izz="1.1941E-06" />
    </inertial>
    <visual>
      <origin
        xyz="0 0 0"
        rpy="0 0 0" />
      <geometry>
        <mesh
          filename="package://Robot_URDF/meshes/FrontUltra_Link.STL" />
      </geometry>
      <material name="green"/>
    </visual>
    <collision>
      <origin
        xyz="0 0 0"
        rpy="0 0 0" />
      <geometry>
        <mesh
          filename="package://Robot_URDF/meshes/FrontUltra_Link.STL" />
      </geometry>
    </collision>
  </link>
  <joint


    name="FrontUltra_Joint"
    type="fixed">
    <origin
      xyz="0 0 0"
      rpy="0 0 0" />
    <parent
      link="base_link" />
    <child


      link="FrontUltra_Link" />
    <axis
      xyz="0 0 0" />
  </joint>
  <link
    name="LeftUltra_Link">
    <inertial>
      <origin
        xyz="4.2017E-06 0.14863 0.040053"
        rpy="0 0 0" />
      <mass
        value="0.0062273" />
      <inertia
        ixx="2.3852E-07"
        ixy="1.3189E-10"
        ixz="-1.9966E-10"
        iyy="1.2204E-06"
        iyz="-2.0237E-09"
        izz="1.1941E-06" />
    </inertial>
    <visual>
      <origin
        xyz="0 0 0"
        rpy="0 0 0" />
      <geometry>
        <mesh
          filename="package://Robot_URDF/meshes/LeftUltra_Link.STL" />
      </geometry>
      <material name="green"/>
    </visual>
    <collision>
      <origin
        xyz="0 0 0"
        rpy="0 0 0" />
      <geometry>
        <mesh
          filename="package://Robot_URDF/meshes/LeftUltra_Link.STL" />
      </geometry>
    </collision>
  </link>
  <joint


    name="LeftUltra_Joint"
    type="fixed">
    <origin
      xyz="0 0 0"
      rpy="0 0 0" />
    <parent
      link="base_link" />
    <child
      link="LeftUltra_Link" />
    <axis
      xyz="0 0 0" />
  </joint>
  <link


    name="Cover_Link">
    <inertial>
      <origin
        xyz="0.0017553 -2.9398E-07 0.0177"
        rpy="0 0 0" />
      <mass
        value="0.33739" />
      <inertia
        ixx="0.0028468"
        ixy="6.2586E-10"
        ixz="1.4453E-06"
        iyy="0.0028585"
        iyz="2.2404E-09"
        izz="0.0053109" />
    </inertial>
    <visual>
      <origin
        xyz="0 0 0"
        rpy="0 0 0" />
      <geometry>
        <mesh
          filename="package://Robot_URDF/meshes/Cover_Link.STL" />
      </geometry>
      <material name="grey"/>
    </visual>
    <collision>
      <origin
        xyz="0 0 0"
        rpy="0 0 0" />
      <geometry>
        <mesh
          filename="package://Robot_URDF/meshes/Cover_Link.STL" />
      </geometry>
    </collision>
  </link>
  <joint


    name="Cover_Joint"
    type="continuous">
    <origin
      xyz="0 0 0"
      rpy="0 0 0" />
    <parent
      link="base_link" />
    <child
      link="Cover_Link" />
    <axis
      xyz="0 0 1" />
  </joint>


  <link
    name="Lidar_Link">
    <inertial>
      <origin
        xyz="0.00058826 0.00017875 0.098458"
        rpy="0 0 0" />
      <mass
        value="0.17056" />
      <inertia
        ixx="8.0287E-05"
        ixy="9.209E-38"
        ixz="-1.7995E-37"
        iyy="8.0287E-05"
        iyz="3.0477E-23"
        izz="0.00012075" />
    </inertial>
    <visual>
      <origin
        xyz="0 0 0"
        rpy="0 0 0" />
      <geometry>
        <mesh
          filename="package://Robot_URDF/meshes/Lidar_Link.STL" />
      </geometry>
      <material name="red"/>
    </visual>
    <collision>
      <origin
        xyz="0 0 0"
        rpy="0 0 0" />
      <geometry>
        <mesh
          filename="package://Robot_URDF/meshes/Lidar_Link.STL" />
      </geometry>
    </collision>
  </link>
  <joint


    name="Lidar_joint"
    type="fixed">
    <origin
      xyz="0 0 0"
      rpy="0 0 0" />
    <parent
      link="Cover_Link" />
    <child
      link="Lidar_Link" />
    <axis
      xyz="0 0 1" />
    <limit
      lower="0"
      upper="0"
      effort="0"
      velocity="0" />
  </joint>
</robot>